<?xml version='1.0' encoding='utf-8'?>
<robot name="gen3_robotiq_2f_140" path="../assets/kinova_gen3/kinova_gen3.urdf">
	<link name="base_link">
		<inertial>
			<origin rpy="0 0 0" xyz="-0.000648 -0.000166 0.084487" />
			<mass value="1.697" />
			<inertia ixx="0.004622" ixy="9E-06" ixz="6E-05" iyy="0.004495" iyz="9E-06" izz="0.002079" />
		</inertial>
		<collision>
			<geometry>
				<sphere radius="0.106585" />
			</geometry>
			<origin xyz="-0.0028389602056587437 0.0010719113916582753 0.04311152284472901" rpy="0 0 0" />
		</collision>
		<collision>
			<geometry>
				<sphere radius="0.111222" />
			</geometry>
			<origin xyz="0.0021220397943412564 -0.0003720886083417247 0.11760152284472901" rpy="0 0 0" />
		</collision>
	<visual name="base_link_visual_1">
			<geometry>
				<sphere radius="0.106585" />
			</geometry>
			<origin xyz="-0.0028389602056587437 0.0010719113916582753 0.04311152284472901" rpy="0 0 0" />
		</visual>
		<visual name="base_link_visual_2">
			<geometry>
				<sphere radius="0.111222" />
			</geometry>
			<origin xyz="0.0021220397943412564 -0.0003720886083417247 0.11760152284472901" rpy="0 0 0" />
		</visual>
	</link>
	<link name="shoulder_link">
		<inertial>
			<origin rpy="0 0 0" xyz="-2.3E-05 -0.010364 -0.07336" />
			<mass value="1.3773" />
			<inertia ixx="0.00457" ixy="1E-06" ixz="2E-06" iyy="0.004831" iyz="0.000448" izz="0.001409" />
		</inertial>
		<collision>
			<geometry>
				<sphere radius="0.091194" />
			</geometry>
			<origin xyz="-0.0015815146350677965 -0.0019901685723896292 -0.04552552105674328" rpy="0 0 0" />
		</collision>
		<collision>
			<geometry>
				<sphere radius="0.080253" />
			</geometry>
			<origin xyz="-0.0021415146350677967 -0.01081216857238963 -0.13783852105674327" rpy="0 0 0" />
		</collision>
		<collision>
			<geometry>
				<sphere radius="0.086897" />
			</geometry>
			<origin xyz="0.004183485364932203 -0.007935168572389628 -0.10612852105674328" rpy="0 0 0" />
		</collision>
		<collision>
			<geometry>
				<sphere radius="0.086099" />
			</geometry>
			<origin xyz="0.004012485364932203 0.0031908314276103715 -0.04079152105674329" rpy="0 0 0" />
		</collision>
	<visual name="shoulder_link_visual_1">
			<geometry>
				<sphere radius="0.091194" />
			</geometry>
			<origin xyz="-0.0015815146350677965 -0.0019901685723896292 -0.04552552105674328" rpy="0 0 0" />
		</visual>
		<visual name="shoulder_link_visual_2">
			<geometry>
				<sphere radius="0.080253" />
			</geometry>
			<origin xyz="-0.0021415146350677967 -0.01081216857238963 -0.13783852105674327" rpy="0 0 0" />
		</visual>
		<visual name="shoulder_link_visual_3">
			<geometry>
				<sphere radius="0.086897" />
			</geometry>
			<origin xyz="0.004183485364932203 -0.007935168572389628 -0.10612852105674328" rpy="0 0 0" />
		</visual>
		<visual name="shoulder_link_visual_4">
			<geometry>
				<sphere radius="0.086099" />
			</geometry>
			<origin xyz="0.004012485364932203 0.0031908314276103715 -0.04079152105674329" rpy="0 0 0" />
		</visual>
	</link>
	<link name="half_arm_1_link">
		<inertial>
			<origin rpy="0 0 0" xyz="-4.4E-05 -0.09958 -0.013278" />
			<mass value="1.1636" />
			<inertia ixx="0.011088" ixy="5E-06" ixz="0" iyy="0.001072" iyz="-0.000691" izz="0.011255" />
		</inertial>
		<collision>
			<geometry>
				<sphere radius="0.090615" />
			</geometry>
			<origin xyz="-0.00035647001452993504 -0.18133966889889402 -0.006131254814246081" rpy="0 0 0" />
		</collision>
		<collision>
			<geometry>
				<sphere radius="0.078671" />
			</geometry>
			<origin xyz="-0.002217470014529935 -0.002781668898894016 -0.02384225481424608" rpy="0 0 0" />
		</collision>
		<collision>
			<geometry>
				<sphere radius="0.079888" />
			</geometry>
			<origin xyz="-0.003008470014529935 -0.11413166889889402 -0.01311525481424608" rpy="0 0 0" />
		</collision>
		<collision>
			<geometry>
				<sphere radius="0.079413" />
			</geometry>
			<origin xyz="0.002277529985470065 -0.05416266889889402 -0.01892125481424608" rpy="0 0 0" />
		</collision>
	<visual name="half_arm_1_link_visual_1">
			<geometry>
				<sphere radius="0.090615" />
			</geometry>
			<origin xyz="-0.00035647001452993504 -0.18133966889889402 -0.006131254814246081" rpy="0 0 0" />
		</visual>
		<visual name="half_arm_1_link_visual_2">
			<geometry>
				<sphere radius="0.078671" />
			</geometry>
			<origin xyz="-0.002217470014529935 -0.002781668898894016 -0.02384225481424608" rpy="0 0 0" />
		</visual>
		<visual name="half_arm_1_link_visual_3">
			<geometry>
				<sphere radius="0.079888" />
			</geometry>
			<origin xyz="-0.003008470014529935 -0.11413166889889402 -0.01311525481424608" rpy="0 0 0" />
		</visual>
		<visual name="half_arm_1_link_visual_4">
			<geometry>
				<sphere radius="0.079413" />
			</geometry>
			<origin xyz="0.002277529985470065 -0.05416266889889402 -0.01892125481424608" rpy="0 0 0" />
		</visual>
	</link>
	<link name="half_arm_2_link">
		<inertial>
			<origin rpy="0 0 0" xyz="-4.4E-05 -0.006641 -0.117892" />
			<mass value="1.1636" />
			<inertia ixx="0.010932" ixy="0" ixz="-7E-06" iyy="0.011127" iyz="0.000606" izz="0.001043" />
		</inertial>
		<collision>
			<geometry>
				<sphere radius="0.092193" />
			</geometry>
			<origin xyz="0.0006058279132786116 0.0001973752587326131 -0.04209310161024811" rpy="0 0 0" />
		</collision>
		<collision>
			<geometry>
				<sphere radius="0.089643" />
			</geometry>
			<origin xyz="0.0019498279132786115 -0.006332624741267386 -0.11276610161024811" rpy="0 0 0" />
		</collision>
		<collision>
			<geometry>
				<sphere radius="0.087097" />
			</geometry>
			<origin xyz="-0.0010401720867213883 -0.011445624741267387 -0.2114391016102481" rpy="0 0 0" />
		</collision>
		<collision>
			<geometry>
				<sphere radius="0.089342" />
			</geometry>
			<origin xyz="0.0005388279132786116 -0.009662624741267386 -0.1692441016102481" rpy="0 0 0" />
		</collision>
	<visual name="half_arm_2_link_visual_1">
			<geometry>
				<sphere radius="0.092193" />
			</geometry>
			<origin xyz="0.0006058279132786116 0.0001973752587326131 -0.04209310161024811" rpy="0 0 0" />
		</visual>
		<visual name="half_arm_2_link_visual_2">
			<geometry>
				<sphere radius="0.089643" />
			</geometry>
			<origin xyz="0.0019498279132786115 -0.006332624741267386 -0.11276610161024811" rpy="0 0 0" />
		</visual>
		<visual name="half_arm_2_link_visual_3">
			<geometry>
				<sphere radius="0.087097" />
			</geometry>
			<origin xyz="-0.0010401720867213883 -0.011445624741267387 -0.2114391016102481" rpy="0 0 0" />
		</visual>
		<visual name="half_arm_2_link_visual_4">
			<geometry>
				<sphere radius="0.089342" />
			</geometry>
			<origin xyz="0.0005388279132786116 -0.009662624741267386 -0.1692441016102481" rpy="0 0 0" />
		</visual>
	</link>
	<link name="forearm_link">
		<inertial>
			<origin rpy="0 0 0" xyz="-1.8E-05 -0.075478 -0.015006" />
			<mass value="0.9302" />
			<inertia ixx="0.008147" ixy="-1E-06" ixz="0" iyy="0.000631" iyz="-0.0005" izz="0.008316" />
		</inertial>
		<collision>
			<geometry>
				<sphere radius="0.071417" />
			</geometry>
			<origin xyz="0.0022488866777107897 -0.14658364036506172 -0.01149060078421775" rpy="0 0 0" />
		</collision>
		<collision>
			<geometry>
				<sphere radius="0.075449" />
			</geometry>
			<origin xyz="0.0008238866777107896 -0.1865976403650617 -0.00758660078421775" rpy="0 0 0" />
		</collision>
		<collision>
			<geometry>
				<sphere radius="0.05023" />
			</geometry>
			<origin xyz="-0.01899511332228921 -0.20562264036506173 0.003261399215782248" rpy="0 0 0" />
		</collision>
		<collision>
			<geometry>
				<sphere radius="0.071334" />
			</geometry>
			<origin xyz="0.00022188667771078964 -0.10397864036506171 -0.01582860078421775" rpy="0 0 0" />
		</collision>
		<collision>
			<geometry>
				<sphere radius="0.070642" />
			</geometry>
			<origin xyz="-0.011813113322289211 -0.05176264036506171 -0.02135360078421775" rpy="0 0 0" />
		</collision>
		<collision>
			<geometry>
				<sphere radius="0.07042" />
			</geometry>
			<origin xyz="0.01178188667771079 -0.05193264036506171 -0.02090460078421775" rpy="0 0 0" />
		</collision>
		<collision>
			<geometry>
				<sphere radius="0.066151" />
			</geometry>
			<origin xyz="-0.016846113322289212 0.0054773596349382975 -0.02516060078421775" rpy="0 0 0" />
		</collision>
		<collision>
			<geometry>
				<sphere radius="0.065691" />
			</geometry>
			<origin xyz="0.005539886677710789 0.017132359634938296 -0.02594860078421775" rpy="0 0 0" />
		</collision>
		<collision>
			<geometry>
				<sphere radius="0.068771" />
			</geometry>
			<origin xyz="0.01423188667771079 -0.004856640365061712 -0.02546460078421775" rpy="0 0 0" />
		</collision>
	<visual name="forearm_link_visual_1">
			<geometry>
				<sphere radius="0.071417" />
			</geometry>
			<origin xyz="0.0022488866777107897 -0.14658364036506172 -0.01149060078421775" rpy="0 0 0" />
		</visual>
		<visual name="forearm_link_visual_2">
			<geometry>
				<sphere radius="0.075449" />
			</geometry>
			<origin xyz="0.0008238866777107896 -0.1865976403650617 -0.00758660078421775" rpy="0 0 0" />
		</visual>
		<visual name="forearm_link_visual_3">
			<geometry>
				<sphere radius="0.05023" />
			</geometry>
			<origin xyz="-0.01899511332228921 -0.20562264036506173 0.003261399215782248" rpy="0 0 0" />
		</visual>
		<visual name="forearm_link_visual_4">
			<geometry>
				<sphere radius="0.071334" />
			</geometry>
			<origin xyz="0.00022188667771078964 -0.10397864036506171 -0.01582860078421775" rpy="0 0 0" />
		</visual>
		<visual name="forearm_link_visual_5">
			<geometry>
				<sphere radius="0.070642" />
			</geometry>
			<origin xyz="-0.011813113322289211 -0.05176264036506171 -0.02135360078421775" rpy="0 0 0" />
		</visual>
		<visual name="forearm_link_visual_6">
			<geometry>
				<sphere radius="0.07042" />
			</geometry>
			<origin xyz="0.01178188667771079 -0.05193264036506171 -0.02090460078421775" rpy="0 0 0" />
		</visual>
		<visual name="forearm_link_visual_7">
			<geometry>
				<sphere radius="0.066151" />
			</geometry>
			<origin xyz="-0.016846113322289212 0.0054773596349382975 -0.02516060078421775" rpy="0 0 0" />
		</visual>
		<visual name="forearm_link_visual_8">
			<geometry>
				<sphere radius="0.065691" />
			</geometry>
			<origin xyz="0.005539886677710789 0.017132359634938296 -0.02594860078421775" rpy="0 0 0" />
		</visual>
		<visual name="forearm_link_visual_9">
			<geometry>
				<sphere radius="0.068771" />
			</geometry>
			<origin xyz="0.01423188667771079 -0.004856640365061712 -0.02546460078421775" rpy="0 0 0" />
		</visual>
	</link>
	<link name="spherical_wrist_1_link">
		<inertial>
			<origin rpy="0 0 0" xyz="1E-06 -0.009432 -0.063883" />
			<mass value="0.6781" />
			<inertia ixx="0.001596" ixy="0" ixz="0" iyy="0.001607" iyz="0.000256" izz="0.000399" />
		</inertial>
		<collision>
			<geometry>
				<sphere radius="0.069272" />
			</geometry>
			<origin xyz="-0.0011128281812018805 -0.013383711588637916 -0.10776088853186075" rpy="0 0 0" />
		</collision>
		<collision>
			<geometry>
				<sphere radius="0.071631" />
			</geometry>
			<origin xyz="-0.00017482818120188062 -0.012066711588637915 -0.08814188853186075" rpy="0 0 0" />
		</collision>
		<collision>
			<geometry>
				<sphere radius="0.05849" />
			</geometry>
			<origin xyz="0.00863317181879812 -0.006105711588637916 -0.11439788853186075" rpy="0 0 0" />
		</collision>
		<collision>
			<geometry>
				<sphere radius="0.068429" />
			</geometry>
			<origin xyz="0.00020117181879811936 -0.006875711588637916 -0.062411888531860756" rpy="0 0 0" />
		</collision>
		<collision>
			<geometry>
				<sphere radius="0.05998" />
			</geometry>
			<origin xyz="0.01176617181879812 -0.005603711588637915 -0.024077888531860756" rpy="0 0 0" />
		</collision>
		<collision>
			<geometry>
				<sphere radius="0.063872" />
			</geometry>
			<origin xyz="-0.0070528281812018805 -0.008839711588637915 -0.029328888531860754" rpy="0 0 0" />
		</collision>
		<collision>
			<geometry>
				<sphere radius="0.072406" />
			</geometry>
			<origin xyz="-0.00041182818120188064 -0.005554711588637915 -0.036324888531860756" rpy="0 0 0" />
		</collision>
		<collision>
			<geometry>
				<sphere radius="0.058017" />
			</geometry>
			<origin xyz="-0.01040582818120188 0.008838288411362083 -0.02230688853186076" rpy="0 0 0" />
		</collision>
		<collision>
			<geometry>
				<sphere radius="0.057836" />
			</geometry>
			<origin xyz="0.009345171818798119 0.011025288411362084 -0.022980888531860755" rpy="0 0 0" />
		</collision>
	<visual name="spherical_wrist_1_link_visual_1">
			<geometry>
				<sphere radius="0.069272" />
			</geometry>
			<origin xyz="-0.0011128281812018805 -0.013383711588637916 -0.10776088853186075" rpy="0 0 0" />
		</visual>
		<visual name="spherical_wrist_1_link_visual_2">
			<geometry>
				<sphere radius="0.071631" />
			</geometry>
			<origin xyz="-0.00017482818120188062 -0.012066711588637915 -0.08814188853186075" rpy="0 0 0" />
		</visual>
		<visual name="spherical_wrist_1_link_visual_3">
			<geometry>
				<sphere radius="0.05849" />
			</geometry>
			<origin xyz="0.00863317181879812 -0.006105711588637916 -0.11439788853186075" rpy="0 0 0" />
		</visual>
		<visual name="spherical_wrist_1_link_visual_4">
			<geometry>
				<sphere radius="0.068429" />
			</geometry>
			<origin xyz="0.00020117181879811936 -0.006875711588637916 -0.062411888531860756" rpy="0 0 0" />
		</visual>
		<visual name="spherical_wrist_1_link_visual_5">
			<geometry>
				<sphere radius="0.05998" />
			</geometry>
			<origin xyz="0.01176617181879812 -0.005603711588637915 -0.024077888531860756" rpy="0 0 0" />
		</visual>
		<visual name="spherical_wrist_1_link_visual_6">
			<geometry>
				<sphere radius="0.063872" />
			</geometry>
			<origin xyz="-0.0070528281812018805 -0.008839711588637915 -0.029328888531860754" rpy="0 0 0" />
		</visual>
		<visual name="spherical_wrist_1_link_visual_7">
			<geometry>
				<sphere radius="0.072406" />
			</geometry>
			<origin xyz="-0.00041182818120188064 -0.005554711588637915 -0.036324888531860756" rpy="0 0 0" />
		</visual>
		<visual name="spherical_wrist_1_link_visual_8">
			<geometry>
				<sphere radius="0.058017" />
			</geometry>
			<origin xyz="-0.01040582818120188 0.008838288411362083 -0.02230688853186076" rpy="0 0 0" />
		</visual>
		<visual name="spherical_wrist_1_link_visual_9">
			<geometry>
				<sphere radius="0.057836" />
			</geometry>
			<origin xyz="0.009345171818798119 0.011025288411362084 -0.022980888531860755" rpy="0 0 0" />
		</visual>
	</link>
	<link name="spherical_wrist_2_link">
		<inertial>
			<origin rpy="0 0 0" xyz="1E-06 -0.045483 -0.00965" />
			<mass value="0.6781" />
			<inertia ixx="0.001641" ixy="0" ixz="0" iyy="0.00041" iyz="-0.000278" izz="0.001641" />
		</inertial>
		<collision>
			<geometry>
				<sphere radius="0.074923" />
			</geometry>
			<origin xyz="-0.0006428535172599168 -0.08541720868890382 -0.005266136467073976" rpy="0 0 0" />
		</collision>
		<collision>
			<geometry>
				<sphere radius="0.064399" />
			</geometry>
			<origin xyz="-0.0033768535172599167 -0.09533520868890383 0.009213863532926025" rpy="0 0 0" />
		</collision>
		<collision>
			<geometry>
				<sphere radius="0.061292" />
			</geometry>
			<origin xyz="0.012980146482740084 -0.09892820868890383 0.001942863532926024" rpy="0 0 0" />
		</collision>
		<collision>
			<geometry>
				<sphere radius="0.067769" />
			</geometry>
			<origin xyz="-0.0003808535172599168 -0.04483420868890382 -0.011461136467073977" rpy="0 0 0" />
		</collision>
		<collision>
			<geometry>
				<sphere radius="0.068003" />
			</geometry>
			<origin xyz="-0.0007038535172599168 -0.019491208688903826 -0.016619136467073976" rpy="0 0 0" />
		</collision>
		<collision>
			<geometry>
				<sphere radius="0.045117" />
			</geometry>
			<origin xyz="-0.018136853517259917 0.008569791311096177 -0.012117136467073976" rpy="0 0 0" />
		</collision>
		<collision>
			<geometry>
				<sphere radius="0.060388" />
			</geometry>
			<origin xyz="-0.004210853517259917 0.005328791311096176 -0.021625136467073976" rpy="0 0 0" />
		</collision>
		<collision>
			<geometry>
				<sphere radius="0.061377" />
			</geometry>
			<origin xyz="0.0028871464827400833 0.004023791311096175 -0.021727136467073978" rpy="0 0 0" />
		</collision>
		<collision>
			<geometry>
				<sphere radius="0.050106" />
			</geometry>
			<origin xyz="0.012565146482740083 0.010904791311096174 -0.014690136467073976" rpy="0 0 0" />
		</collision>
	<visual name="spherical_wrist_2_link_visual_1">
			<geometry>
				<sphere radius="0.074923" />
			</geometry>
			<origin xyz="-0.0006428535172599168 -0.08541720868890382 -0.005266136467073976" rpy="0 0 0" />
		</visual>
		<visual name="spherical_wrist_2_link_visual_2">
			<geometry>
				<sphere radius="0.064399" />
			</geometry>
			<origin xyz="-0.0033768535172599167 -0.09533520868890383 0.009213863532926025" rpy="0 0 0" />
		</visual>
		<visual name="spherical_wrist_2_link_visual_3">
			<geometry>
				<sphere radius="0.061292" />
			</geometry>
			<origin xyz="0.012980146482740084 -0.09892820868890383 0.001942863532926024" rpy="0 0 0" />
		</visual>
		<visual name="spherical_wrist_2_link_visual_4">
			<geometry>
				<sphere radius="0.067769" />
			</geometry>
			<origin xyz="-0.0003808535172599168 -0.04483420868890382 -0.011461136467073977" rpy="0 0 0" />
		</visual>
		<visual name="spherical_wrist_2_link_visual_5">
			<geometry>
				<sphere radius="0.068003" />
			</geometry>
			<origin xyz="-0.0007038535172599168 -0.019491208688903826 -0.016619136467073976" rpy="0 0 0" />
		</visual>
		<visual name="spherical_wrist_2_link_visual_6">
			<geometry>
				<sphere radius="0.045117" />
			</geometry>
			<origin xyz="-0.018136853517259917 0.008569791311096177 -0.012117136467073976" rpy="0 0 0" />
		</visual>
		<visual name="spherical_wrist_2_link_visual_7">
			<geometry>
				<sphere radius="0.060388" />
			</geometry>
			<origin xyz="-0.004210853517259917 0.005328791311096176 -0.021625136467073976" rpy="0 0 0" />
		</visual>
		<visual name="spherical_wrist_2_link_visual_8">
			<geometry>
				<sphere radius="0.061377" />
			</geometry>
			<origin xyz="0.0028871464827400833 0.004023791311096175 -0.021727136467073978" rpy="0 0 0" />
		</visual>
		<visual name="spherical_wrist_2_link_visual_9">
			<geometry>
				<sphere radius="0.050106" />
			</geometry>
			<origin xyz="0.012565146482740083 0.010904791311096174 -0.014690136467073976" rpy="0 0 0" />
		</visual>
	</link>
	<link name="bracelet_link">
		<inertial>
			<origin rpy="0 0 0" xyz="-9.3E-05 0.000132 -0.022905" />
			<mass value="0.364" />
			<inertia ixx="0.000214" ixy="0" ixz="1E-06" iyy="0.000223" iyz="-2E-06" izz="0.00024" />
		</inertial>
		<collision>
			<geometry>
				<sphere radius="0.075089" />
			</geometry>
			<origin xyz="-0.0002936601190272949 -2.8636385271732176e-05 -0.03292566625354537" rpy="0 0 0" />
		</collision>
	<visual name="bracelet_link_visual_1">
			<geometry>
				<sphere radius="0.075089" />
			</geometry>
			<origin xyz="-0.0002936601190272949 -2.8636385271732176e-05 -0.03292566625354537" rpy="0 0 0" />
		</visual>
	</link>
	<link name="end_effector_link" />
	<link name="tool_frame" />
	<link name="robotiq_arg2f_base_link">
		<inertial>
			<origin rpy="0 0 0" xyz="8.625E-08 -4.6583E-06 0.03145" />
			<mass value="0.22652" />
			<inertia ixx="0.00020005" ixy="-4.2442E-10" ixz="-2.9069E-10" iyy="0.00017832" iyz="-3.4402E-08" izz="0.00013478" />
		</inertial>
		<collision>
			<geometry>
				<sphere radius="0.053503" />
			</geometry>
			<origin xyz="-1e-06 -1e-06 0.03976211301029474" rpy="0 0 0" />
		</collision>
	<visual name="robotiq_arg2f_base_link_visual_1">
			<geometry>
				<sphere radius="0.053503" />
			</geometry>
			<origin xyz="-1e-06 -1e-06 0.03976211301029474" rpy="0 0 0" />
		</visual>
	</link>
	<link name="left_outer_knuckle">
		<inertial>
			<origin rpy="0 0 0" xyz="-0.000200000000003065 0.0199435877845359 0.0292245259211331" />
			<mass value="0.00853198276973456" />
			<inertia ixx="2.89328108496468E-06" ixy="-1.57935047237397E-19" ixz="-1.93980378593255E-19" iyy="1.86719750325683E-06" iyz="-1.21858577871576E-06" izz="1.21905238907251E-06" />
		</inertial>
		<collision>
			<geometry>
				<sphere radius="0.012743" />
			</geometry>
			<origin xyz="-0.00019999966025352478 0.02048839362347126 0.02052081721776724" rpy="0 0 0" />
		</collision>
		<collision>
			<geometry>
				<sphere radius="0.013744" />
			</geometry>
			<origin xyz="-0.00019999966025352478 0.018234393623471262 0.01590081721776724" rpy="0 0 0" />
		</collision>
		<collision>
			<geometry>
				<sphere radius="0.013928" />
			</geometry>
			<origin xyz="-0.00019999966025352478 0.011400393623471259 0.009848817217767238" rpy="0 0 0" />
		</collision>
		<collision>
			<geometry>
				<sphere radius="0.008064" />
			</geometry>
			<origin xyz="-0.00018199966025352478 -0.014014606376528741 -0.01488018278223276" rpy="0 0 0" />
		</collision>
		<collision>
			<geometry>
				<sphere radius="0.010542" />
			</geometry>
			<origin xyz="-0.0006929996602535247 -0.00623760637652874 -0.007067182782232761" rpy="0 0 0" />
		</collision>
		<collision>
			<geometry>
				<sphere radius="0.01151" />
			</geometry>
			<origin xyz="-0.00017099966025352478 0.0023013936234712604 0.0013738172177672385" rpy="0 0 0" />
		</collision>
	<visual name="left_outer_knuckle_visual_1">
			<geometry>
				<sphere radius="0.012743" />
			</geometry>
			<origin xyz="-0.00019999966025352478 0.02048839362347126 0.02052081721776724" rpy="0 0 0" />
		</visual>
		<visual name="left_outer_knuckle_visual_2">
			<geometry>
				<sphere radius="0.013744" />
			</geometry>
			<origin xyz="-0.00019999966025352478 0.018234393623471262 0.01590081721776724" rpy="0 0 0" />
		</visual>
		<visual name="left_outer_knuckle_visual_3">
			<geometry>
				<sphere radius="0.013928" />
			</geometry>
			<origin xyz="-0.00019999966025352478 0.011400393623471259 0.009848817217767238" rpy="0 0 0" />
		</visual>
		<visual name="left_outer_knuckle_visual_4">
			<geometry>
				<sphere radius="0.008064" />
			</geometry>
			<origin xyz="-0.00018199966025352478 -0.014014606376528741 -0.01488018278223276" rpy="0 0 0" />
		</visual>
		<visual name="left_outer_knuckle_visual_5">
			<geometry>
				<sphere radius="0.010542" />
			</geometry>
			<origin xyz="-0.0006929996602535247 -0.00623760637652874 -0.007067182782232761" rpy="0 0 0" />
		</visual>
		<visual name="left_outer_knuckle_visual_6">
			<geometry>
				<sphere radius="0.01151" />
			</geometry>
			<origin xyz="-0.00017099966025352478 0.0023013936234712604 0.0013738172177672385" rpy="0 0 0" />
		</visual>
	</link>
	<link name="left_outer_finger">
		<inertial>
			<origin rpy="0 0 0" xyz="0.00030115855001899 0.0373907951953854 -0.0208027427000385" />
			<mass value="0.022614240507152" />
			<inertia ixx="1.52518312458174E-05" ixy="9.76583423954399E-10" ixz="-5.43838577022588E-10" iyy="6.17694243867776E-06" iyz="6.78636130740228E-06" izz="1.16494917907219E-05" />
		</inertial>
		<collision>
			<geometry>
				<sphere radius="0.015017" />
			</geometry>
			<origin xyz="-0.0007529954268336296 0.038191566359490156 -0.014729038674920798" rpy="0 0 0" />
		</collision>
		<collision>
			<geometry>
				<sphere radius="0.01438" />
			</geometry>
			<origin xyz="-0.0002139954268336296 0.08000556635949016 -0.027427038674920797" rpy="0 0 0" />
		</collision>
		<collision>
			<geometry>
				<sphere radius="0.015713" />
			</geometry>
			<origin xyz="0.0002440045731663704 0.027060566359490154 -0.011313038674920797" rpy="0 0 0" />
		</collision>
		<collision>
			<geometry>
				<sphere radius="0.015813" />
			</geometry>
			<origin xyz="-0.0005939954268336296 0.015680566359490156 -0.007732038674920797" rpy="0 0 0" />
		</collision>
		<collision>
			<geometry>
				<sphere radius="0.014978" />
			</geometry>
			<origin xyz="-0.00611599542683363 0.055784566359490154 -0.020123038674920796" rpy="0 0 0" />
		</collision>
		<collision>
			<geometry>
				<sphere radius="0.014533" />
			</geometry>
			<origin xyz="0.00555600457316637 0.051975566359490154 -0.018955038674920797" rpy="0 0 0" />
		</collision>
		<collision>
			<geometry>
				<sphere radius="0.015732" />
			</geometry>
			<origin xyz="-0.0001989954268336296 0.0037445663594901576 -0.0018980386749207975" rpy="0 0 0" />
		</collision>
		<collision>
			<geometry>
				<sphere radius="0.015163" />
			</geometry>
			<origin xyz="0.0001950045731663704 0.06990656635949016 -0.024438038674920795" rpy="0 0 0" />
		</collision>
	<visual name="left_outer_finger_visual_1">
			<geometry>
				<sphere radius="0.015017" />
			</geometry>
			<origin xyz="-0.0007529954268336296 0.038191566359490156 -0.014729038674920798" rpy="0 0 0" />
		</visual>
		<visual name="left_outer_finger_visual_2">
			<geometry>
				<sphere radius="0.01438" />
			</geometry>
			<origin xyz="-0.0002139954268336296 0.08000556635949016 -0.027427038674920797" rpy="0 0 0" />
		</visual>
		<visual name="left_outer_finger_visual_3">
			<geometry>
				<sphere radius="0.015713" />
			</geometry>
			<origin xyz="0.0002440045731663704 0.027060566359490154 -0.011313038674920797" rpy="0 0 0" />
		</visual>
		<visual name="left_outer_finger_visual_4">
			<geometry>
				<sphere radius="0.015813" />
			</geometry>
			<origin xyz="-0.0005939954268336296 0.015680566359490156 -0.007732038674920797" rpy="0 0 0" />
		</visual>
		<visual name="left_outer_finger_visual_5">
			<geometry>
				<sphere radius="0.014978" />
			</geometry>
			<origin xyz="-0.00611599542683363 0.055784566359490154 -0.020123038674920796" rpy="0 0 0" />
		</visual>
		<visual name="left_outer_finger_visual_6">
			<geometry>
				<sphere radius="0.014533" />
			</geometry>
			<origin xyz="0.00555600457316637 0.051975566359490154 -0.018955038674920797" rpy="0 0 0" />
		</visual>
		<visual name="left_outer_finger_visual_7">
			<geometry>
				<sphere radius="0.015732" />
			</geometry>
			<origin xyz="-0.0001989954268336296 0.0037445663594901576 -0.0018980386749207975" rpy="0 0 0" />
		</visual>
		<visual name="left_outer_finger_visual_8">
			<geometry>
				<sphere radius="0.015163" />
			</geometry>
			<origin xyz="0.0001950045731663704 0.06990656635949016 -0.024438038674920795" rpy="0 0 0" />
		</visual>
	</link>
	<link name="left_inner_finger">
		<inertial>
			<origin rpy="0 0 0" xyz="0.000299999999999317 0.0160078233491243 -0.0136945669206257" />
			<mass value="0.0104003125914103" />
			<inertia ixx="2.71909453810972E-06" ixy="1.35402465472579E-21" ixz="-7.1817349065269E-22" iyy="7.69100314106116E-07" iyz="6.74715432769696E-07" izz="2.30315190420171E-06" />
		</inertial>
		<collision>
			<geometry>
				<sphere radius="0.01223" />
			</geometry>
			<origin xyz="-0.00019899826326966286 0.03709378533244133 -0.017156007689893248" rpy="0 0 0" />
		</collision>
		<collision>
			<geometry>
				<sphere radius="0.012987" />
			</geometry>
			<origin xyz="-0.00019999826326966286 0.02389478533244133 -0.015688007689893244" rpy="0 0 0" />
		</collision>
		<collision>
			<geometry>
				<sphere radius="0.013304" />
			</geometry>
			<origin xyz="-0.00019999826326966286 0.0074657853324413305 -0.016401007689893245" rpy="0 0 0" />
		</collision>
		<collision>
			<geometry>
				<sphere radius="0.011631" />
			</geometry>
			<origin xyz="-0.00019999826326966286 0.0023397853324413284 -0.002310007689893246" rpy="0 0 0" />
		</collision>
		<collision>
			<geometry>
				<sphere radius="0.013312" />
			</geometry>
			<origin xyz="-0.00019999826326966286 0.01608078533244133 -0.008831007689893245" rpy="0 0 0" />
		</collision>
	<visual name="left_inner_finger_visual_1">
			<geometry>
				<sphere radius="0.01223" />
			</geometry>
			<origin xyz="-0.00019899826326966286 0.03709378533244133 -0.017156007689893248" rpy="0 0 0" />
		</visual>
		<visual name="left_inner_finger_visual_2">
			<geometry>
				<sphere radius="0.012987" />
			</geometry>
			<origin xyz="-0.00019999826326966286 0.02389478533244133 -0.015688007689893244" rpy="0 0 0" />
		</visual>
		<visual name="left_inner_finger_visual_3">
			<geometry>
				<sphere radius="0.013304" />
			</geometry>
			<origin xyz="-0.00019999826326966286 0.0074657853324413305 -0.016401007689893245" rpy="0 0 0" />
		</visual>
		<visual name="left_inner_finger_visual_4">
			<geometry>
				<sphere radius="0.011631" />
			</geometry>
			<origin xyz="-0.00019999826326966286 0.0023397853324413284 -0.002310007689893246" rpy="0 0 0" />
		</visual>
		<visual name="left_inner_finger_visual_5">
			<geometry>
				<sphere radius="0.013312" />
			</geometry>
			<origin xyz="-0.00019999826326966286 0.01608078533244133 -0.008831007689893245" rpy="0 0 0" />
		</visual>
	</link>
	<link name="left_inner_finger_pad">
		<collision>
			<geometry>
				<sphere radius="0.01168" />
			</geometry>
			<origin xyz="0.006303 -0.028186 0.0" rpy="0 0 0" />
		</collision>
		<collision>
			<geometry>
				<sphere radius="0.012372" />
			</geometry>
			<origin xyz="-0.008853 -0.02494 0.0" rpy="0 0 0" />
		</collision>
		<collision>
			<geometry>
				<sphere radius="0.011967" />
			</geometry>
			<origin xyz="0.006878 -0.012499 0.0" rpy="0 0 0" />
		</collision>
		<collision>
			<geometry>
				<sphere radius="0.012126" />
			</geometry>
			<origin xyz="-0.010292 -0.003527 0.0" rpy="0 0 0" />
		</collision>
		<collision>
			<geometry>
				<sphere radius="0.012565" />
			</geometry>
			<origin xyz="0.008954 0.006853 0.0" rpy="0 0 0" />
		</collision>
		<collision>
			<geometry>
				<sphere radius="0.010995" />
			</geometry>
			<origin xyz="-0.006813 0.014358 0.0" rpy="0 0 0" />
		</collision>
		<collision>
			<geometry>
				<sphere radius="0.012008" />
			</geometry>
			<origin xyz="0.007685 0.026253 0.0" rpy="0 0 0" />
		</collision>
		<collision>
			<geometry>
				<sphere radius="0.010647" />
			</geometry>
			<origin xyz="-0.00758 0.028348 0.0" rpy="0 0 0" />
		</collision>
	<visual name="left_inner_finger_pad_visual_1">
			<geometry>
				<sphere radius="0.01168" />
			</geometry>
			<origin xyz="0.006303 -0.028186 0.0" rpy="0 0 0" />
		</visual>
		<visual name="left_inner_finger_pad_visual_2">
			<geometry>
				<sphere radius="0.012372" />
			</geometry>
			<origin xyz="-0.008853 -0.02494 0.0" rpy="0 0 0" />
		</visual>
		<visual name="left_inner_finger_pad_visual_3">
			<geometry>
				<sphere radius="0.011967" />
			</geometry>
			<origin xyz="0.006878 -0.012499 0.0" rpy="0 0 0" />
		</visual>
		<visual name="left_inner_finger_pad_visual_4">
			<geometry>
				<sphere radius="0.012126" />
			</geometry>
			<origin xyz="-0.010292 -0.003527 0.0" rpy="0 0 0" />
		</visual>
		<visual name="left_inner_finger_pad_visual_5">
			<geometry>
				<sphere radius="0.012565" />
			</geometry>
			<origin xyz="0.008954 0.006853 0.0" rpy="0 0 0" />
		</visual>
		<visual name="left_inner_finger_pad_visual_6">
			<geometry>
				<sphere radius="0.010995" />
			</geometry>
			<origin xyz="-0.006813 0.014358 0.0" rpy="0 0 0" />
		</visual>
		<visual name="left_inner_finger_pad_visual_7">
			<geometry>
				<sphere radius="0.012008" />
			</geometry>
			<origin xyz="0.007685 0.026253 0.0" rpy="0 0 0" />
		</visual>
		<visual name="left_inner_finger_pad_visual_8">
			<geometry>
				<sphere radius="0.010647" />
			</geometry>
			<origin xyz="-0.00758 0.028348 0.0" rpy="0 0 0" />
		</visual>
	</link>
	<link name="left_inner_knuckle">
		<inertial>
			<origin rpy="0 0 0" xyz="0.000123011831763771 0.0507850843201817 0.00103968640075166" />
			<mass value="0.0271177346495152" />
			<inertia ixx="2.61910379223783E-05" ixy="-2.43616858946494E-07" ixz="-6.37789906117123E-09" iyy="2.8270243746167E-06" iyz="-5.37200748039765E-07" izz="2.83695868220296E-05" />
		</inertial>
		<collision>
			<geometry>
				<sphere radius="0.017433" />
			</geometry>
			<origin xyz="-0.011491000846385956 0.009454694714218378 -0.00021026292836666112" rpy="0 0 0" />
		</collision>
		<collision>
			<geometry>
				<sphere radius="0.017072" />
			</geometry>
			<origin xyz="0.008844999153614044 0.006851694714218377 -0.00015226292836666112" rpy="0 0 0" />
		</collision>
		<collision>
			<geometry>
				<sphere radius="0.018156" />
			</geometry>
			<origin xyz="0.009525999153614044 0.03400569471421838 -0.000754262928366661" rpy="0 0 0" />
		</collision>
		<collision>
			<geometry>
				<sphere radius="0.017869" />
			</geometry>
			<origin xyz="-0.010610000846385956 0.040353694714218374 -0.0008952629283666611" rpy="0 0 0" />
		</collision>
		<collision>
			<geometry>
				<sphere radius="0.016357" />
			</geometry>
			<origin xyz="0.010540999153614044 0.06187269471421838 -0.001373262928366661" rpy="0 0 0" />
		</collision>
		<collision>
			<geometry>
				<sphere radius="0.017531" />
			</geometry>
			<origin xyz="-0.008726000846385955 0.07194569471421838 -0.001597262928366661" rpy="0 0 0" />
		</collision>
		<collision>
			<geometry>
				<sphere radius="0.016813" />
			</geometry>
			<origin xyz="0.013444999153614044 0.09027369471421838 -0.002003262928366661" rpy="0 0 0" />
		</collision>
		<collision>
			<geometry>
				<sphere radius="0.014551" />
			</geometry>
			<origin xyz="-0.002933000846385956 0.09701569471421838 -0.002153262928366661" rpy="0 0 0" />
		</collision>
	<visual name="left_inner_knuckle_visual_1">
			<geometry>
				<sphere radius="0.017433" />
			</geometry>
			<origin xyz="-0.011491000846385956 0.009454694714218378 -0.00021026292836666112" rpy="0 0 0" />
		</visual>
		<visual name="left_inner_knuckle_visual_2">
			<geometry>
				<sphere radius="0.017072" />
			</geometry>
			<origin xyz="0.008844999153614044 0.006851694714218377 -0.00015226292836666112" rpy="0 0 0" />
		</visual>
		<visual name="left_inner_knuckle_visual_3">
			<geometry>
				<sphere radius="0.018156" />
			</geometry>
			<origin xyz="0.009525999153614044 0.03400569471421838 -0.000754262928366661" rpy="0 0 0" />
		</visual>
		<visual name="left_inner_knuckle_visual_4">
			<geometry>
				<sphere radius="0.017869" />
			</geometry>
			<origin xyz="-0.010610000846385956 0.040353694714218374 -0.0008952629283666611" rpy="0 0 0" />
		</visual>
		<visual name="left_inner_knuckle_visual_5">
			<geometry>
				<sphere radius="0.016357" />
			</geometry>
			<origin xyz="0.010540999153614044 0.06187269471421838 -0.001373262928366661" rpy="0 0 0" />
		</visual>
		<visual name="left_inner_knuckle_visual_6">
			<geometry>
				<sphere radius="0.017531" />
			</geometry>
			<origin xyz="-0.008726000846385955 0.07194569471421838 -0.001597262928366661" rpy="0 0 0" />
		</visual>
		<visual name="left_inner_knuckle_visual_7">
			<geometry>
				<sphere radius="0.016813" />
			</geometry>
			<origin xyz="0.013444999153614044 0.09027369471421838 -0.002003262928366661" rpy="0 0 0" />
		</visual>
		<visual name="left_inner_knuckle_visual_8">
			<geometry>
				<sphere radius="0.014551" />
			</geometry>
			<origin xyz="-0.002933000846385956 0.09701569471421838 -0.002153262928366661" rpy="0 0 0" />
		</visual>
	</link>
	<link name="right_outer_knuckle">
		<inertial>
			<origin rpy="0 0 0" xyz="-0.000200000000003065 0.0199435877845359 0.0292245259211331" />
			<mass value="0.00853198276973456" />
			<inertia ixx="2.89328108496468E-06" ixy="-1.57935047237397E-19" ixz="-1.93980378593255E-19" iyy="1.86719750325683E-06" iyz="-1.21858577871576E-06" izz="1.21905238907251E-06" />
		</inertial>
		<collision>
			<geometry>
				<sphere radius="0.012743" />
			</geometry>
			<origin xyz="-0.00019999966025352478 0.02048839362347126 0.02052081721776724" rpy="0 0 0" />
		</collision>
		<collision>
			<geometry>
				<sphere radius="0.013744" />
			</geometry>
			<origin xyz="-0.00019999966025352478 0.018234393623471262 0.01590081721776724" rpy="0 0 0" />
		</collision>
		<collision>
			<geometry>
				<sphere radius="0.013928" />
			</geometry>
			<origin xyz="-0.00019999966025352478 0.011400393623471259 0.009848817217767238" rpy="0 0 0" />
		</collision>
		<collision>
			<geometry>
				<sphere radius="0.008064" />
			</geometry>
			<origin xyz="-0.00018199966025352478 -0.014014606376528741 -0.01488018278223276" rpy="0 0 0" />
		</collision>
		<collision>
			<geometry>
				<sphere radius="0.010542" />
			</geometry>
			<origin xyz="-0.0006929996602535247 -0.00623760637652874 -0.007067182782232761" rpy="0 0 0" />
		</collision>
		<collision>
			<geometry>
				<sphere radius="0.01151" />
			</geometry>
			<origin xyz="-0.00017099966025352478 0.0023013936234712604 0.0013738172177672385" rpy="0 0 0" />
		</collision>
	<visual name="right_outer_knuckle_visual_1">
			<geometry>
				<sphere radius="0.012743" />
			</geometry>
			<origin xyz="-0.00019999966025352478 0.02048839362347126 0.02052081721776724" rpy="0 0 0" />
		</visual>
		<visual name="right_outer_knuckle_visual_2">
			<geometry>
				<sphere radius="0.013744" />
			</geometry>
			<origin xyz="-0.00019999966025352478 0.018234393623471262 0.01590081721776724" rpy="0 0 0" />
		</visual>
		<visual name="right_outer_knuckle_visual_3">
			<geometry>
				<sphere radius="0.013928" />
			</geometry>
			<origin xyz="-0.00019999966025352478 0.011400393623471259 0.009848817217767238" rpy="0 0 0" />
		</visual>
		<visual name="right_outer_knuckle_visual_4">
			<geometry>
				<sphere radius="0.008064" />
			</geometry>
			<origin xyz="-0.00018199966025352478 -0.014014606376528741 -0.01488018278223276" rpy="0 0 0" />
		</visual>
		<visual name="right_outer_knuckle_visual_5">
			<geometry>
				<sphere radius="0.010542" />
			</geometry>
			<origin xyz="-0.0006929996602535247 -0.00623760637652874 -0.007067182782232761" rpy="0 0 0" />
		</visual>
		<visual name="right_outer_knuckle_visual_6">
			<geometry>
				<sphere radius="0.01151" />
			</geometry>
			<origin xyz="-0.00017099966025352478 0.0023013936234712604 0.0013738172177672385" rpy="0 0 0" />
		</visual>
	</link>
	<link name="right_outer_finger">
		<inertial>
			<origin rpy="0 0 0" xyz="0.00030115855001899 0.0373907951953854 -0.0208027427000385" />
			<mass value="0.022614240507152" />
			<inertia ixx="1.52518312458174E-05" ixy="9.76583423954399E-10" ixz="-5.43838577022588E-10" iyy="6.17694243867776E-06" iyz="6.78636130740228E-06" izz="1.16494917907219E-05" />
		</inertial>
		<collision>
			<geometry>
				<sphere radius="0.015017" />
			</geometry>
			<origin xyz="-0.0007529954268336296 0.038191566359490156 -0.014729038674920798" rpy="0 0 0" />
		</collision>
		<collision>
			<geometry>
				<sphere radius="0.01438" />
			</geometry>
			<origin xyz="-0.0002139954268336296 0.08000556635949016 -0.027427038674920797" rpy="0 0 0" />
		</collision>
		<collision>
			<geometry>
				<sphere radius="0.015713" />
			</geometry>
			<origin xyz="0.0002440045731663704 0.027060566359490154 -0.011313038674920797" rpy="0 0 0" />
		</collision>
		<collision>
			<geometry>
				<sphere radius="0.015813" />
			</geometry>
			<origin xyz="-0.0005939954268336296 0.015680566359490156 -0.007732038674920797" rpy="0 0 0" />
		</collision>
		<collision>
			<geometry>
				<sphere radius="0.014978" />
			</geometry>
			<origin xyz="-0.00611599542683363 0.055784566359490154 -0.020123038674920796" rpy="0 0 0" />
		</collision>
		<collision>
			<geometry>
				<sphere radius="0.014533" />
			</geometry>
			<origin xyz="0.00555600457316637 0.051975566359490154 -0.018955038674920797" rpy="0 0 0" />
		</collision>
		<collision>
			<geometry>
				<sphere radius="0.015732" />
			</geometry>
			<origin xyz="-0.0001989954268336296 0.0037445663594901576 -0.0018980386749207975" rpy="0 0 0" />
		</collision>
		<collision>
			<geometry>
				<sphere radius="0.015163" />
			</geometry>
			<origin xyz="0.0001950045731663704 0.06990656635949016 -0.024438038674920795" rpy="0 0 0" />
		</collision>
	<visual name="right_outer_finger_visual_1">
			<geometry>
				<sphere radius="0.015017" />
			</geometry>
			<origin xyz="-0.0007529954268336296 0.038191566359490156 -0.014729038674920798" rpy="0 0 0" />
		</visual>
		<visual name="right_outer_finger_visual_2">
			<geometry>
				<sphere radius="0.01438" />
			</geometry>
			<origin xyz="-0.0002139954268336296 0.08000556635949016 -0.027427038674920797" rpy="0 0 0" />
		</visual>
		<visual name="right_outer_finger_visual_3">
			<geometry>
				<sphere radius="0.015713" />
			</geometry>
			<origin xyz="0.0002440045731663704 0.027060566359490154 -0.011313038674920797" rpy="0 0 0" />
		</visual>
		<visual name="right_outer_finger_visual_4">
			<geometry>
				<sphere radius="0.015813" />
			</geometry>
			<origin xyz="-0.0005939954268336296 0.015680566359490156 -0.007732038674920797" rpy="0 0 0" />
		</visual>
		<visual name="right_outer_finger_visual_5">
			<geometry>
				<sphere radius="0.014978" />
			</geometry>
			<origin xyz="-0.00611599542683363 0.055784566359490154 -0.020123038674920796" rpy="0 0 0" />
		</visual>
		<visual name="right_outer_finger_visual_6">
			<geometry>
				<sphere radius="0.014533" />
			</geometry>
			<origin xyz="0.00555600457316637 0.051975566359490154 -0.018955038674920797" rpy="0 0 0" />
		</visual>
		<visual name="right_outer_finger_visual_7">
			<geometry>
				<sphere radius="0.015732" />
			</geometry>
			<origin xyz="-0.0001989954268336296 0.0037445663594901576 -0.0018980386749207975" rpy="0 0 0" />
		</visual>
		<visual name="right_outer_finger_visual_8">
			<geometry>
				<sphere radius="0.015163" />
			</geometry>
			<origin xyz="0.0001950045731663704 0.06990656635949016 -0.024438038674920795" rpy="0 0 0" />
		</visual>
	</link>
	<link name="right_inner_finger">
		<inertial>
			<origin rpy="0 0 0" xyz="0.000299999999999317 0.0160078233491243 -0.0136945669206257" />
			<mass value="0.0104003125914103" />
			<inertia ixx="2.71909453810972E-06" ixy="1.35402465472579E-21" ixz="-7.1817349065269E-22" iyy="7.69100314106116E-07" iyz="6.74715432769696E-07" izz="2.30315190420171E-06" />
		</inertial>
		<collision>
			<geometry>
				<sphere radius="0.01223" />
			</geometry>
			<origin xyz="-0.00019899826326966286 0.03709378533244133 -0.017156007689893248" rpy="0 0 0" />
		</collision>
		<collision>
			<geometry>
				<sphere radius="0.012987" />
			</geometry>
			<origin xyz="-0.00019999826326966286 0.02389478533244133 -0.015688007689893244" rpy="0 0 0" />
		</collision>
		<collision>
			<geometry>
				<sphere radius="0.013304" />
			</geometry>
			<origin xyz="-0.00019999826326966286 0.0074657853324413305 -0.016401007689893245" rpy="0 0 0" />
		</collision>
		<collision>
			<geometry>
				<sphere radius="0.011631" />
			</geometry>
			<origin xyz="-0.00019999826326966286 0.0023397853324413284 -0.002310007689893246" rpy="0 0 0" />
		</collision>
		<collision>
			<geometry>
				<sphere radius="0.013312" />
			</geometry>
			<origin xyz="-0.00019999826326966286 0.01608078533244133 -0.008831007689893245" rpy="0 0 0" />
		</collision>
	<visual name="right_inner_finger_visual_1">
			<geometry>
				<sphere radius="0.01223" />
			</geometry>
			<origin xyz="-0.00019899826326966286 0.03709378533244133 -0.017156007689893248" rpy="0 0 0" />
		</visual>
		<visual name="right_inner_finger_visual_2">
			<geometry>
				<sphere radius="0.012987" />
			</geometry>
			<origin xyz="-0.00019999826326966286 0.02389478533244133 -0.015688007689893244" rpy="0 0 0" />
		</visual>
		<visual name="right_inner_finger_visual_3">
			<geometry>
				<sphere radius="0.013304" />
			</geometry>
			<origin xyz="-0.00019999826326966286 0.0074657853324413305 -0.016401007689893245" rpy="0 0 0" />
		</visual>
		<visual name="right_inner_finger_visual_4">
			<geometry>
				<sphere radius="0.011631" />
			</geometry>
			<origin xyz="-0.00019999826326966286 0.0023397853324413284 -0.002310007689893246" rpy="0 0 0" />
		</visual>
		<visual name="right_inner_finger_visual_5">
			<geometry>
				<sphere radius="0.013312" />
			</geometry>
			<origin xyz="-0.00019999826326966286 0.01608078533244133 -0.008831007689893245" rpy="0 0 0" />
		</visual>
	</link>
	<link name="right_inner_finger_pad">
		<collision>
			<geometry>
				<sphere radius="0.01168" />
			</geometry>
			<origin xyz="0.006303 -0.028186 0.0" rpy="0 0 0" />
		</collision>
		<collision>
			<geometry>
				<sphere radius="0.012372" />
			</geometry>
			<origin xyz="-0.008853 -0.02494 0.0" rpy="0 0 0" />
		</collision>
		<collision>
			<geometry>
				<sphere radius="0.011967" />
			</geometry>
			<origin xyz="0.006878 -0.012499 0.0" rpy="0 0 0" />
		</collision>
		<collision>
			<geometry>
				<sphere radius="0.012126" />
			</geometry>
			<origin xyz="-0.010292 -0.003527 0.0" rpy="0 0 0" />
		</collision>
		<collision>
			<geometry>
				<sphere radius="0.012565" />
			</geometry>
			<origin xyz="0.008954 0.006853 0.0" rpy="0 0 0" />
		</collision>
		<collision>
			<geometry>
				<sphere radius="0.010995" />
			</geometry>
			<origin xyz="-0.006813 0.014358 0.0" rpy="0 0 0" />
		</collision>
		<collision>
			<geometry>
				<sphere radius="0.012008" />
			</geometry>
			<origin xyz="0.007685 0.026253 0.0" rpy="0 0 0" />
		</collision>
		<collision>
			<geometry>
				<sphere radius="0.010647" />
			</geometry>
			<origin xyz="-0.00758 0.028348 0.0" rpy="0 0 0" />
		</collision>
	<visual name="right_inner_finger_pad_visual_1">
			<geometry>
				<sphere radius="0.01168" />
			</geometry>
			<origin xyz="0.006303 -0.028186 0.0" rpy="0 0 0" />
		</visual>
		<visual name="right_inner_finger_pad_visual_2">
			<geometry>
				<sphere radius="0.012372" />
			</geometry>
			<origin xyz="-0.008853 -0.02494 0.0" rpy="0 0 0" />
		</visual>
		<visual name="right_inner_finger_pad_visual_3">
			<geometry>
				<sphere radius="0.011967" />
			</geometry>
			<origin xyz="0.006878 -0.012499 0.0" rpy="0 0 0" />
		</visual>
		<visual name="right_inner_finger_pad_visual_4">
			<geometry>
				<sphere radius="0.012126" />
			</geometry>
			<origin xyz="-0.010292 -0.003527 0.0" rpy="0 0 0" />
		</visual>
		<visual name="right_inner_finger_pad_visual_5">
			<geometry>
				<sphere radius="0.012565" />
			</geometry>
			<origin xyz="0.008954 0.006853 0.0" rpy="0 0 0" />
		</visual>
		<visual name="right_inner_finger_pad_visual_6">
			<geometry>
				<sphere radius="0.010995" />
			</geometry>
			<origin xyz="-0.006813 0.014358 0.0" rpy="0 0 0" />
		</visual>
		<visual name="right_inner_finger_pad_visual_7">
			<geometry>
				<sphere radius="0.012008" />
			</geometry>
			<origin xyz="0.007685 0.026253 0.0" rpy="0 0 0" />
		</visual>
		<visual name="right_inner_finger_pad_visual_8">
			<geometry>
				<sphere radius="0.010647" />
			</geometry>
			<origin xyz="-0.00758 0.028348 0.0" rpy="0 0 0" />
		</visual>
	</link>
	<link name="right_inner_knuckle">
		<inertial>
			<origin rpy="0 0 0" xyz="0.000123011831763771 0.0507850843201817 0.00103968640075166" />
			<mass value="0.0271177346495152" />
			<inertia ixx="2.61910379223783E-05" ixy="-2.43616858946494E-07" ixz="-6.37789906117123E-09" iyy="2.8270243746167E-06" iyz="-5.37200748039765E-07" izz="2.83695868220296E-05" />
		</inertial>
		<collision>
			<geometry>
				<sphere radius="0.017433" />
			</geometry>
			<origin xyz="-0.011491000846385956 0.009454694714218378 -0.00021026292836666112" rpy="0 0 0" />
		</collision>
		<collision>
			<geometry>
				<sphere radius="0.017072" />
			</geometry>
			<origin xyz="0.008844999153614044 0.006851694714218377 -0.00015226292836666112" rpy="0 0 0" />
		</collision>
		<collision>
			<geometry>
				<sphere radius="0.018156" />
			</geometry>
			<origin xyz="0.009525999153614044 0.03400569471421838 -0.000754262928366661" rpy="0 0 0" />
		</collision>
		<collision>
			<geometry>
				<sphere radius="0.017869" />
			</geometry>
			<origin xyz="-0.010610000846385956 0.040353694714218374 -0.0008952629283666611" rpy="0 0 0" />
		</collision>
		<collision>
			<geometry>
				<sphere radius="0.016357" />
			</geometry>
			<origin xyz="0.010540999153614044 0.06187269471421838 -0.001373262928366661" rpy="0 0 0" />
		</collision>
		<collision>
			<geometry>
				<sphere radius="0.017531" />
			</geometry>
			<origin xyz="-0.008726000846385955 0.07194569471421838 -0.001597262928366661" rpy="0 0 0" />
		</collision>
		<collision>
			<geometry>
				<sphere radius="0.016813" />
			</geometry>
			<origin xyz="0.013444999153614044 0.09027369471421838 -0.002003262928366661" rpy="0 0 0" />
		</collision>
		<collision>
			<geometry>
				<sphere radius="0.014551" />
			</geometry>
			<origin xyz="-0.002933000846385956 0.09701569471421838 -0.002153262928366661" rpy="0 0 0" />
		</collision>
	<visual name="right_inner_knuckle_visual_1">
			<geometry>
				<sphere radius="0.017433" />
			</geometry>
			<origin xyz="-0.011491000846385956 0.009454694714218378 -0.00021026292836666112" rpy="0 0 0" />
		</visual>
		<visual name="right_inner_knuckle_visual_2">
			<geometry>
				<sphere radius="0.017072" />
			</geometry>
			<origin xyz="0.008844999153614044 0.006851694714218377 -0.00015226292836666112" rpy="0 0 0" />
		</visual>
		<visual name="right_inner_knuckle_visual_3">
			<geometry>
				<sphere radius="0.018156" />
			</geometry>
			<origin xyz="0.009525999153614044 0.03400569471421838 -0.000754262928366661" rpy="0 0 0" />
		</visual>
		<visual name="right_inner_knuckle_visual_4">
			<geometry>
				<sphere radius="0.017869" />
			</geometry>
			<origin xyz="-0.010610000846385956 0.040353694714218374 -0.0008952629283666611" rpy="0 0 0" />
		</visual>
		<visual name="right_inner_knuckle_visual_5">
			<geometry>
				<sphere radius="0.016357" />
			</geometry>
			<origin xyz="0.010540999153614044 0.06187269471421838 -0.001373262928366661" rpy="0 0 0" />
		</visual>
		<visual name="right_inner_knuckle_visual_6">
			<geometry>
				<sphere radius="0.017531" />
			</geometry>
			<origin xyz="-0.008726000846385955 0.07194569471421838 -0.001597262928366661" rpy="0 0 0" />
		</visual>
		<visual name="right_inner_knuckle_visual_7">
			<geometry>
				<sphere radius="0.016813" />
			</geometry>
			<origin xyz="0.013444999153614044 0.09027369471421838 -0.002003262928366661" rpy="0 0 0" />
		</visual>
		<visual name="right_inner_knuckle_visual_8">
			<geometry>
				<sphere radius="0.014551" />
			</geometry>
			<origin xyz="-0.002933000846385956 0.09701569471421838 -0.002153262928366661" rpy="0 0 0" />
		</visual>
	</link>
	<joint name="joint_1" type="continuous">
		<origin rpy="3.1416 2.7629E-18 -4.9305E-36" xyz="0 0 0.15643" />
		<parent link="base_link" />
		<child link="shoulder_link" />
		<axis xyz="0 0 1" />
		<limit effort="39" velocity="1.3963" />
	</joint>
	<joint name="joint_2" type="revolute">
		<origin rpy="1.5708 2.1343E-17 -1.1102E-16" xyz="0 0.005375 -0.12838" />
		<parent link="shoulder_link" />
		<child link="half_arm_1_link" />
		<axis xyz="0 0 1" />
		<limit effort="39" lower="-2.24" upper="2.24" velocity="1.3963" />
	</joint>
	<joint name="joint_3" type="continuous">
		<origin rpy="-1.5708 1.2326E-32 -2.9122E-16" xyz="0 -0.21038 -0.006375" />
		<parent link="half_arm_1_link" />
		<child link="half_arm_2_link" />
		<axis xyz="0 0 1" />
		<limit effort="39" velocity="1.3963" />
	</joint>
	<joint name="joint_4" type="revolute">
		<origin rpy="1.5708 -6.6954E-17 -1.6653E-16" xyz="0 0.006375 -0.21038" />
		<parent link="half_arm_2_link" />
		<child link="forearm_link" />
		<axis xyz="0 0 1" />
		<limit effort="39" lower="-2.57" upper="2.57" velocity="1.3963" />
	</joint>
	<joint name="joint_5" type="continuous">
		<origin rpy="-1.5708 2.2204E-16 -6.373E-17" xyz="0 -0.20843 -0.006375" />
		<parent link="forearm_link" />
		<child link="spherical_wrist_1_link" />
		<axis xyz="0 0 1" />
		<limit effort="9" velocity="1.2218" />
	</joint>
	<joint name="joint_6" type="revolute">
		<origin rpy="1.5708 9.2076E-28 -8.2157E-15" xyz="0 0.00017505 -0.10593" />
		<parent link="spherical_wrist_1_link" />
		<child link="spherical_wrist_2_link" />
		<axis xyz="0 0 1" />
		<limit effort="9" lower="-2.09" upper="2.09" velocity="1.2218" />
	</joint>
	<joint name="joint_7" type="continuous">
		<origin rpy="-1.5708 -5.5511E-17 9.6396E-17" xyz="0 -0.10593 -0.00017505" />
		<parent link="spherical_wrist_2_link" />
		<child link="bracelet_link" />
		<axis xyz="0 0 1" />
		<limit effort="9" velocity="1.2218" />
	</joint>
	<joint name="end_effector" type="fixed">
		<origin rpy="3.14159265358979 1.09937075168372E-32 0" xyz="0 0 -0.0615250000000001" />
		<parent link="bracelet_link" />
		<child link="end_effector_link" />
		<axis xyz="0 0 0" />
	</joint>
	<joint name="tool_frame_joint" type="fixed">
		<origin rpy="0 0 0" xyz="0 0 0.20" />
		<parent link="end_effector_link" />
		<child link="tool_frame" />
		<axis xyz="0 0 0" />
	</joint>
	<joint name="gripper_base_joint" type="fixed">
		<parent link="end_effector_link" />
		<child link="robotiq_arg2f_base_link" />
		<origin rpy="0.0 0.0 1.57" xyz="0.0 0.0 0.0" />
	</joint>
	<joint name="finger_joint" type="fixed">
		<origin rpy="2.2957963267948966 0 0" xyz="0 -0.030601 0.054905" />
		<parent link="robotiq_arg2f_base_link" />
		<child link="left_outer_knuckle" />
		<axis xyz="-1 0 0" />
		<limit effort="1000" lower="0" upper="0.7" velocity="2.0" />
	</joint>
	<joint name="left_outer_finger_joint" type="fixed">
		<origin rpy="0 0 0" xyz="0 0.01821998610742 0.0260018192872234" />
		<parent link="left_outer_knuckle" />
		<child link="left_outer_finger" />
		<axis xyz="1 0 0" />
	</joint>
	<joint name="left_inner_knuckle_joint" type="fixed">
		<origin rpy="2.2957963267948966 0 0.0" xyz="0 -0.0127 0.06142" />
		<parent link="robotiq_arg2f_base_link" />
		<child link="left_inner_knuckle" />
		<axis xyz="1 0 0" />
		<limit effort="1000" lower="-0.8757" upper="0.8757" velocity="2.0" />
		<mimic joint="finger_joint" multiplier="-1" offset="0" />
	</joint>
	<joint name="left_inner_finger_joint" type="fixed">
		<origin rpy="-0.725 0 0" xyz="0 0.0817554015893473 -0.0282203446692936" />
		<parent link="left_outer_finger" />
		<child link="left_inner_finger" />
		<axis xyz="1 0 0" />
		<limit effort="1000" lower="-0.8757" upper="0.8757" velocity="2.0" />
		<mimic joint="finger_joint" multiplier="1" offset="0" />
	</joint>
	<joint name="left_inner_finger_pad_joint" type="fixed">
		<origin rpy="0 0 0" xyz="0 0.0457554015893473 -0.0272203446692936" />
		<parent link="left_inner_finger" />
		<child link="left_inner_finger_pad" />
		<axis xyz="0 0 1" />
	</joint>
	<joint name="right_outer_knuckle_joint" type="fixed">
		<origin rpy="2.2957963267948966 0 3.141592653589793" xyz="0 0.030601 0.054905" />
		<parent link="robotiq_arg2f_base_link" />
		<child link="right_outer_knuckle" />
		<axis xyz="1 0 0" />
		<limit effort="1000" lower="-0.725" upper="0.725" velocity="2.0" />
		<mimic joint="finger_joint" multiplier="-1" offset="0" />
	</joint>
	<joint name="right_outer_finger_joint" type="fixed">
		<origin rpy="0 0 0" xyz="0 0.01821998610742 0.0260018192872234" />
		<parent link="right_outer_knuckle" />
		<child link="right_outer_finger" />
		<axis xyz="1 0 0" />
	</joint>
	<joint name="right_inner_knuckle_joint" type="fixed">
		<origin rpy="2.2957963267948966 0 -3.141592653589793" xyz="0 0.0127 0.06142" />
		<parent link="robotiq_arg2f_base_link" />
		<child link="right_inner_knuckle" />
		<axis xyz="1 0 0" />
		<limit effort="1000" lower="-0.8757" upper="0.8757" velocity="2.0" />
		<mimic joint="finger_joint" multiplier="-1" offset="0" />
	</joint>
	<joint name="right_inner_finger_joint" type="fixed">
		<origin rpy="-0.725 0 0" xyz="0 0.0817554015893473 -0.0282203446692936" />
		<parent link="right_outer_finger" />
		<child link="right_inner_finger" />
		<axis xyz="1 0 0" />
		<limit effort="1000" lower="-0.8757" upper="0.8757" velocity="2.0" />
		<mimic joint="finger_joint" multiplier="1" offset="0" />
	</joint>
	<joint name="right_inner_finger_pad_joint" type="fixed">
		<origin rpy="0 0 0" xyz="0 0.0457554015893473 -0.0272203446692936" />
		<parent link="right_inner_finger" />
		<child link="right_inner_finger_pad" />
		<axis xyz="0 0 1" />
	</joint>
	<gazebo reference="robotiq_arg2f_base_link">
		<material>Gazebo/Black</material>
	</gazebo>
	<gazebo reference="left_outer_knuckle">
		<visual>
			<material>
				<ambient>0.792156862745098 0.819607843137255 0.933333333333333 1</ambient>
				<diffuse>0.792156862745098 0.819607843137255 0.933333333333333 1</diffuse>
			</material>
		</visual>
	</gazebo>
	<gazebo reference="left_outer_finger">
		<material>Gazebo/Black</material>
	</gazebo>
	<gazebo reference="left_inner_finger">
		<material>Gazebo/Black</material>
	</gazebo>
	<gazebo reference="left_inner_knuckle">
		<material>Gazebo/Black</material>
	</gazebo>
	<gazebo reference="right_outer_knuckle">
		<visual>
			<material>
				<ambient>0.792156862745098 0.819607843137255 0.933333333333333 1</ambient>
				<diffuse>0.792156862745098 0.819607843137255 0.933333333333333 1</diffuse>
			</material>
		</visual>
	</gazebo>
	<gazebo reference="right_outer_finger">
		<material>Gazebo/Black</material>
	</gazebo>
	<gazebo reference="right_inner_finger">
		<material>Gazebo/Black</material>
	</gazebo>
	<gazebo reference="right_inner_knuckle">
		<material>Gazebo/Black</material>
	</gazebo>
</robot>