<?xml version="1.0" encoding="utf-8"?>
<robot name="Yaskawa_gp4" xmlns:xacro="http://ros.org/wiki/xacro" path="../assets/gp4_lego/gp4.urdf">
	<link name="world"></link>
	<link name="base"></link>
	<link name="base_link">
		<inertial>
			<origin xyz="-0.073983 0.00022734 0.13031" rpy="0 0 0"></origin>
			<mass value="42.212"></mass>
			<inertia ixx="0.64296" ixy="0.0012624" ixz="-0.068804" iyy="1.2709" iyz="-0.0010754" izz="1.3497"></inertia>
		</inertial>
		<visual>
			<geometry>
				<mesh filename="gp4/base_link.stl"></mesh>
			</geometry>
		</visual>
		<collision>
			<geometry>
				<sphere radius="0.145161"></sphere>
			</geometry>
			<origin xyz="-0.030634019150972365 -2.3021806955337534e-05 0.07861094463970823" rpy="0 0 0"></origin>
		</collision>
	</link>
	<link name="link_1">
		<inertial>
			<origin xyz="0.058962 0.24363 -0.018725" rpy="0 0 0"></origin>
			<mass value="37.265"></mass>
			<inertia ixx="0.95018" ixy="-0.14402" ixz="-0.064915" iyy="1.0578" iyz="0.037699" izz="1.094"></inertia>
		</inertial>
		<visual>
			<geometry>
				<mesh filename="gp4/link_1.stl"></mesh>
			</geometry>
		</visual>
		<collision>
			<geometry>
				<sphere radius="0.116389"></sphere>
			</geometry>
			<origin xyz="-0.003947012403726578 0.00042604842877388 -0.07957098797893525" rpy="0 0 0"></origin>
		</collision>
		<collision>
			<geometry>
				<sphere radius="0.113803"></sphere>
			</geometry>
			<origin xyz="-0.0007430124037265777 2.048428773880005e-06 -0.004696987978935245" rpy="0 0 0"></origin>
		</collision>
	</link>
	<link name="link_2">
		<inertial>
			<origin xyz="3.5083E-05 0.39008 0.15036" rpy="0 0 0"></origin>
			<mass value="22.632"></mass>
			<inertia ixx="1.7745" ixy="-0.0054743" ixz="0.00063015" iyy="0.15511" iyz="-0.09224" izz="1.826"></inertia>
		</inertial>
		<visual>
			<geometry>
				<mesh filename="gp4/link_2.stl"></mesh>
			</geometry>
		</visual>
		<collision>
			<geometry>
				<sphere radius="0.127532"></sphere>
			</geometry>
			<origin xyz="-0.030863542814776535 0.0033705792253270798 0.12160294650002601" rpy="0 0 0"></origin>
		</collision>
		<collision>
			<geometry>
				<sphere radius="0.116702"></sphere>
			</geometry>
			<origin xyz="-0.009157542814776536 0.01002657922532708 0.024801946500026012" rpy="0 0 0"></origin>
		</collision>
		<collision>
			<geometry>
				<sphere radius="0.099999"></sphere>
			</geometry>
			<origin xyz="-0.013797542814776536 -0.06003142077467292 0.226649946500026" rpy="0 0 0"></origin>
		</collision>
		<collision>
			<geometry>
				<sphere radius="0.091318"></sphere>
			</geometry>
			<origin xyz="-0.009467542814776537 0.06468457922532708 0.23478694650002602" rpy="0 0 0"></origin>
		</collision>
	</link>
	<link name="link_3">
		<inertial>
			<origin xyz="0.086423 0.14427 -0.035793" rpy="0 0 0"></origin>
			<mass value="28.467"></mass>
			<inertia ixx="0.65771" ixy="-0.13627" ixz="-0.026219" iyy="0.52683" iyz="0.051956" izz="0.69722"></inertia>
		</inertial>
		<visual>
			<geometry>
				<mesh filename="gp4/link_3.stl"></mesh>
			</geometry>
		</visual>
		<collision>
			<geometry>
				<sphere radius="0.108494"></sphere>
			</geometry>
			<origin xyz="0.01155402389073372 0.00649709885430336 -0.0011659696273803712" rpy="0 0 0"></origin>
		</collision>
	</link>
	<link name="link_4">
		<inertial>
			<origin xyz="0.37337 0.00033491 0.012656" rpy="0 0 0"></origin>
			<mass value="7.629"></mass>
			<inertia ixx="0.018151" ixy="-0.00033527" ixz="-0.031589" iyy="0.48072" iyz="3.3917E-05" izz="0.47647"></inertia>
		</inertial>
		<visual>
			<geometry>
				<mesh filename="gp4/link_4.stl"></mesh>
			</geometry>
		</visual>
		<collision>
			<geometry>
				<sphere radius="0.087739"></sphere>
			</geometry>
			<origin xyz="-0.12295802021551133 0.00021011886656284332 0.00045296638298034667" rpy="0 0 0"></origin>
		</collision>
		<collision>
			<geometry>
				<sphere radius="0.080663"></sphere>
			</geometry>
			<origin xyz="-0.022747020215511324 0.0008201188665628433 -0.0003460336170196534" rpy="0 0 0"></origin>
		</collision>
	</link>
	<link name="link_5">
		<inertial>
			<origin xyz="0.062818 3.3289E-05 0.0048991" rpy="0 0 0"></origin>
			<mass value="2.5794"></mass>
			<inertia ixx="0.015161" ixy="-2.4835E-06" ixz="0.0016647" iyy="0.021382" iyz="-2.248E-06" izz="0.013473"></inertia>
		</inertial>
		<visual>
			<geometry>
				<mesh filename="gp4/link_5.stl"></mesh>
			</geometry>
		</visual>
		<collision>
			<geometry>
				<sphere radius="0.065188"></sphere>
			</geometry>
			<origin xyz="0.014196006263256074 -0.0016248214304447174 -9.637603759765764e-07" rpy="0 0 0"></origin>
		</collision>
	</link>
	<link name="link_6">
		<inertial>
			<origin xyz="0.00015982 -0.00063018 -0.008266" rpy="0 0 0"></origin>
			<mass value="0.10811"></mass>
			<inertia ixx="9.0129E-05" ixy="-1.0891E-08" ixz="9.1598E-09" iyy="9.2026E-05" iyz="-2.749E-07" izz="0.00017818"></inertia>
		</inertial>
		<visual>
			<geometry>
				<mesh filename="gp4/link_6.stl"></mesh>
			</geometry>
		</visual>
		<collision>
			<geometry>
				<sphere radius="0.022972"></sphere>
			</geometry>
			<origin xyz="0.06725001335144043 -5.284726309776306e-05 -0.012774910593032837" rpy="0 0 0"></origin>
		</collision>
		<collision>
			<geometry>
				<sphere radius="0.023049"></sphere>
			</geometry>
			<origin xyz="0.06725001335144043 -0.010521847263097763 0.0068190894069671635" rpy="0 0 0"></origin>
		</collision>
		<collision>
			<geometry>
				<sphere radius="0.022052"></sphere>
			</geometry>
			<origin xyz="0.06726901335144043 0.011999152736902236 0.006232089406967163" rpy="0 0 0"></origin>
		</collision>
	</link>
	<link name="fts">
		<collision>
			<geometry>
				<sphere radius="0.063261"></sphere>
			</geometry>
			<origin xyz="2e-06 0.0 2e-06" rpy="0 0 0"></origin>
		</collision>
		<visual>
			<origin xyz="0 0 0" rpy="0 0 0"></origin>
			<geometry>
				<cylinder length="0.0505" radius="0.0472"></cylinder>
			</geometry>
		</visual>
		<inertial>
			<mass value="1e-5"></mass>
			<origin xyz="0 0 0" rpy="0 0 0"></origin>
			<inertia ixx="1e-6" ixy="0" ixz="0" iyy="1e-6" iyz="0" izz="1e-6"></inertia>
		</inertial>
	</link>
	<link name="link_tool">
		<inertial>
			<origin xyz="0 0 0" rpy="0 0 0"></origin>
			<mass value="0.10811"></mass>
			<inertia ixx="9.0129E-05" ixy="-1.0891E-08" ixz="9.1598E-09" iyy="9.2026E-05" iyz="-2.749E-07" izz="0.00017818"></inertia>
		</inertial>
		<visual>
			<origin xyz="0 0 0" rpy="0 0 0"></origin>
			<geometry>
				<mesh filename="eoat/tool_with_cam_gen35.stl"></mesh>
			</geometry>
		</visual>
		<collision>
			<geometry>
				<sphere radius="0.029354"></sphere>
			</geometry>
			<origin xyz="-0.0017652605978558111 0.000506512432185927 0.050171901189082865" rpy="0 0 0"></origin>
		</collision>
		<collision>
			<geometry>
				<sphere radius="0.0346"></sphere>
			</geometry>
			<origin xyz="0.0003217394021441889 0.005155512432185927 0.015226901189082861" rpy="0 0 0"></origin>
		</collision>
		<collision>
			<geometry>
				<sphere radius="0.035525"></sphere>
			</geometry>
			<origin xyz="0.001834739402144189 -0.002429487567814073 0.016496901189082862" rpy="0 0 0"></origin>
		</collision>
		<collision>
			<geometry>
				<sphere radius="0.031597"></sphere>
			</geometry>
			<origin xyz="-0.00804926059785581 -0.002479487567814073 0.014040901189082862" rpy="0 0 0"></origin>
		</collision>
	</link>
	<link name="flange"></link>
	<joint name="world_fixed" type="fixed">
		<parent link="world"></parent>
		<child link="base"></child>
	</joint>
	<joint name="base_link-base" type="fixed">
		<origin xyz="0 0 0.0" rpy="0 0 0"></origin>
		<parent link="base"></parent>
		<child link="base_link"></child>
	</joint>
	<joint name="joint_1" type="revolute">
		<parent link="base_link"></parent>
		<child link="link_1"></child>
		<origin xyz="0 0 0.330" rpy="0 0 0"></origin>
		<axis xyz="0 0 1"></axis>
		<limit effort="200" lower="-2.9670597283903604" upper="2.9670597283903604" velocity="2"></limit>
	</joint>
	<joint name="joint_2" type="revolute">
		<parent link="link_1"></parent>
		<child link="link_2"></child>
		<origin xyz="0 0 0" rpy="0 0 0"></origin>
		<axis xyz="0 1 0"></axis>
		<limit effort="200" lower="-1.9198621771937625" upper="2.2689280275926285" velocity="2"></limit>
	</joint>
	<joint name="joint_3" type="revolute">
		<parent link="link_2"></parent>
		<child link="link_3"></child>
		<origin xyz="0 0 0.260" rpy="0 0 0"></origin>
		<axis xyz="0 -1 0"></axis>
		<limit effort="200" lower="-1.1344640137963142" upper="3.490658503988659" velocity="2"></limit>
	</joint>
	<joint name="joint_4" type="revolute">
		<parent link="link_3"></parent>
		<child link="link_4"></child>
		<origin xyz="0.290 0 0.015" rpy="0 0 0"></origin>
		<axis xyz="-1 0 0"></axis>
		<limit effort="200" lower="-3.490658503988659" upper="3.490658503988659" velocity="2"></limit>
	</joint>
	<joint name="joint_5" type="revolute">
		<parent link="link_4"></parent>
		<child link="link_5"></child>
		<origin xyz="0 0 0" rpy="0 0 0"></origin>
		<axis xyz="0 -1 0"></axis>
		<limit effort="200" lower="-1.98968" upper="1.98968" velocity="2"></limit>
	</joint>
	<joint name="joint_6" type="revolute">
		<parent link="link_5"></parent>
		<child link="link_6"></child>
		<origin xyz="0 0 0" rpy="0 0 0"></origin>
		<axis xyz="-1 0 0"></axis>
		<limit effort="200" lower="-7.941248096574199" upper="7.941248096574199" velocity="2"></limit>
	</joint>
	<joint name="joint_6_t-flange" type="fixed">
		<origin xyz="0.072 0 0" rpy="0 0 0"></origin>
		<parent link="link_6"></parent>
		<child link="flange"></child>
	</joint>
	<joint name="link_6_fts" type="fixed">
		<origin rpy="0 1.5707963267948966 0" xyz="0.02525 0 0"></origin>
		<parent link="flange"></parent>
		<child link="fts"></child>
	</joint>
	<joint name="fts_tool" type="fixed">
		<origin rpy="0 0 3.141592653589793" xyz="0 0 0.02525"></origin>
		<parent link="fts"></parent>
		<child link="link_tool"></child>
	</joint>
</robot>